Workbook

Sheet CAMPO FUERTE
B1: CAMPO FUERTE
B3: FECHA | C3: TIPO COMP | D3: NUMERO | E3: FECHA VTO | F3: IMPORTE | G3: OBSERVACIONES | H3: FECHA COBRO | I3: DS. DIF
B4: 45075 | C4: FAC | D4: A0000200001276 | F4: 7865000
B5: 45078 | C5: FAC | D5: A0000200001278 | F5: 7865000
B8: TOTAL DEVENGADO INFORMADO | F8: 0
B9: TOTAL FACTURADO | E9: total fact | F9: 0
B10: DIFERENCIA | E10: dif deveg | F10: =+F8-F9 -> 0
B12: TOTAL DEUDA | F12: 0

Sheet AUTOMAT
B1: AUTOMAT ARGENTINA SA
B3: FECHA | C3: TIPO COMP | D3: NUMERO | E3: FECHA VTO | F3: IMPORTE | G3: OBSERVACIONES | H3: FECHA COBRO | I3: DS. DIF
F4: -194.45
B5: 45232 | C5: FAC | D5: 200001287 | E5: =+B5+10 -> 45242 | F5: 12100000 | G5: SERV PUB | H5: SALDADA | I5: -
B6: 45239 | C6: FAC | D6: 200001288 | E6: =+B6+10 -> 45249 | F6: 2936298.5 | G6: SERV PUB | H6: SALDADA | I6: -
B7: 45239 | C7: FAC | D7: 200001289 | E7: =+B7+10 -> 45249 | F7: 2064353.2 | G7: OBRAS | H7: SALDADA | I7: -
B8: 45287 | C8: FAC | D8: 200001292 | E8: =+B8+10 -> 45297 | F8: 11783973 | G8: OCTUBRE SERV PUB | H8: SALDADA | I8: -
B9: 45287 | C9: FAC | D9: 200001293 | E9: =+B9+10 -> 45297 | F9: 850644.52 | G9: OCTUBRE OBRAS | H9: SALDADA | I9: -
B10: 45296 | C10: FAC | D10: 200001297 | E10: =+B10+10 -> 45306 | F10: 14124738 | G10: NOVIEMBRE SERV PUB | H10: SALDADA | I10: -
B11: 45296 | C11: FAC | D11: 200001298 | E11: =+B11+10 -> 45306 | F11: 419125.85 | G11: NOVIEMBRE OBRAS | H11: SALDADA | I11: -
B12: 45356 | C12: FAC | D12: 200001305 | E12: =+B12+30 -> 45386 | F12: 99210.32 | G12: ENERO 2024 OBRAS | H12: SALDADA | I12: -
B13: 45357 | C13: FAC | D13: 200001306 | E13: =+B13+30 -> 45387 | F13: 9451975.5 | G13: ENERO 2024 SERV PUB | H13: SALDADA | I13: -
B14: 45376 | C14: FAC | D14: 200001311 | E14: =+B14+30 -> 45406 | F14: 9047172.8 | G14: FEBRERO 2024 SERV PUB | H14: - | I14: -
B15: 45376 | C15: FAC | D15: 200001312 | E15: =+B15+30 -> 45406 | F15: 2192303.3 | G15: FEBRERO 2024 OBRAS | H15: - | I15: -
B16: 45377 | C16: NC | D16: 200000095 | E16: =+B16+30 -> 45407 | F16: -9047172.8 | G16: APLICA A FC 2-1311 | H16: - | I16: -
B17: 45377 | C17: NC | D17: 200000096 | E17: =+B17+30 -> 45407 | F17: -2192303.3 | G17: APLICA A FC 2-1312 | H17: - | I17: -
B18: 45377 | C18: NC | D18: 200000098 | E18: =+B18+30 -> 45407 | F18: -4684530.8 | G18: APLICA A FC 2-1306 | H18: - | I18: -
B19: 45407 | C19: FAC | D19: 200001317 | E19: =+B19+30 -> 45437 | F19: 9047172.8 | G19: FEBRERO 2024 SERV PUB | H19: SALDADA | I19: -
B20: 45407 | C20: FAC | D20: 200001318 | E20: =+B20+30 -> 45437 | F20: 2192303.3 | G20: FEBRERO 2024 OBRAS | H20: SALDADA | I20: -
B21: 45435 | C21: FAC | D21: 200001319 | E21: =+B21+30 -> 45465 | F21: 6954748.9 | G21: INDUMAT | H21: SALDADA | I21: -
B22: 45440 | C22: FAC | D22: 200001320 | E22: =+B22+30 -> 45470 | F22: 19705714 | G22: MARZO 2024 SERV PUB | H22: SALDADA | I22: -
B23: 45440 | C23: FAC | D23: 200001321 | E23: =+B23+30 -> 45470 | F23: 691428.57 | G23: MARZO 2024 OBRAS | H23: SALDADA | I23: -
... B34: 45505 | C34: FAC | D34: 200001337 | E34: =+B34+30 -> 45535 | F34: 1210000 | G34: MTTO FLOTA OBRAS | H34: SALDADA | I34: -
B35: 45537 | C35: FAC | D35: 200001340 | E35: =+B35+0 -> 45537 | F35: 1512500 | G35: MTTO FLOTA FLUVIOMAT | H35: SALDADA | I35: -
B36: 45537 | C36: FAC | D36: 200001342 | E36: =+B36+0 -> 45537 | F36: 17545000 | G36: MTTO FLOTA SERV PUB | H36: SALDADA | I36: -
B37: 45537 | C37: FAC | D37: 200001343 | E37: =+B37+0 -> 45537 | F37: 1210000 | G37: MTTO FLOTA OBRAS | H37: SALDADA | I37: -
B38: 45568 | C38: FAC | D38: 200001346 | E38: =+B38+0 -> 45568 | F38: 1902551.4 | G38: MTTO FLOTA FLUVIOMAT | H38: SALDADA | I38: -
B39: 45568 | C39: FAC | D39: 200001348 | E39: =+B39+0 -> 45568 | F39: 22069596 | G39: MTTO FLOTA SERV PUB | H39: SALDADA | I39: -
B40: 45568 | C40: FAC | D40: 200001349 | E40: =+B40+0 -> 45568 | F40: 1522041.1 | G40: MTTO FLOTA OBRAS | H40: SALDADA | I40: -
B41: 45600 | C41: FAC | D41: 200001350 | E41: =+B41+0 -> 45600 | F41: 1968554.9 | G41: MTTO FLOTA FLUVIOMAT | H41: SALDADA | I41: -
B42: 45600 | C42: FAC | D42: 200001352 | E42: =+B42+0 -> 45600 | F42: 22835236 | G42: MTTO FLOTA SERV PUB | H42: SALDADA | I42: -
B43: 45600 | C43: FAC | D43: 200001353 | E43: =+B43+0 -> 45600 | F43: 15748844 | G43: MTTO FLOTA OBRAS | H43: SALDADA | I43: -
B44: 45629 | C44: FAC | D44: A200001354 | E44: =+B44+0 -> 45629 | F44: 2021543.2 | G44: MTTO FLOTA FLUVIOMAT | H44: SALDADA | I44: -
B45: 45629 | C45: FAC | D45: A200001356 | E45: =+B45+0 -> 45629 | F45: 23449901 | G45: MTTO FLOTA SERV PUB | H45: SALDADA | I45: -
B46: 45629 | C46: FAC | D46: A200001357 | E46: =+B46+0 -> 45629 | F46: 1617234.6 | G46: MTTO FLOTA OBRAS | H46: SALDADA | I46: -
B47: 45659 | C47: FAC | D47: A200001358 | E47: =+B47+0 -> 45659 | F47: 2070597.1 | G47: MTTO FLOTA FLUVIOMAT | H47: SALDADA | I47: -
B48: 45659 | C48: FAC | D48: A200001360 | E48: =+B48+0 -> 45659 | F48: 24018926 | G48: MTTO FLOTA SERV PUB | H48: SALDADA | I48: -
B49: 45659 | C49: FAC | D49: A200001361 | E49: =+B49+0 -> 45659 | F49: 1656477.7 | G49: MTTO FLOTA OBRAS | H49: SALDADA | I49: -
B50: 45691 | C50: FAC | D50: A200001364 | E50: =+B50+0 -> 45691 | F50: 2126588.2 | G50: MTTO FLOTA FLUVIOMAT | H50: SALDADA | I50: -
B51: 45691 | C51: FAC | D51: A200001365 | E51: =+B51+0 -> 45691 | F51: 24668423 | G51: MTTO FLOTA SERV PUB | H51: SALDADA | I51: -
...

Sheet FLUVIOMAT
B1: FLUVIOMAT SA
B3: FECHA | C3: TIPO COMP | D3: NUMERO | E3: FECHA VTO | F3: IMPORTE | G3: OBSERVACIONES | H3: FECHA COBRO | I3: DS. DIF
B4: 45239 | C4: FAC | D4: 200001291 | E4: =+B4+10 -> 45249 | F4: 1590109.4 | H4: SALDADA | I4: -
B5: 45287 | C5: FAC | D5: 200001294 | E5: =+B5+10 -> 45297 | F5: 1913267.7 | G5: OCTUBRE | H5: SALDADA | I5: -
B6: 45296 | C6: FAC | D6: 200001299 | E6: =+B6+10 -> 45306 | F6: 6578807.5 | G6: NOVIEMBRE | H6: SALDADA | I6: -
B7: 45356 | C7: FAC | D7: 200001302 | E7: =+B7+30 -> 45386 | F7: 1047788.6 | G7: ENERO 2024 | H7: SALDADA | I7: -
B8: 45376 | C8: FAC | D8: 200001309 | E8: =+B8+30 -> 45406 | F8: 1951725.6 | G8: DISEÑO MODIF DE BARCAZA | H8: - | I8: -
B9: 45376 | C9: FAC | D9: 200001310 | E9: =+B9+30 -> 45406 | F9: 723775.97 | G9: FEBRERO 2024 | H9: - | I9: -
B10: 45377 | C10: NC | D10: 200000093 | E10: =+B10+30 -> 45407 | F10: -1951725.6 | G10: APLICA A FC 2-1309 | H10: - | I10: -
B11: 45377 | C11: NC | D11: 200000094 | E11: =+B11+30 -> 45407 | F11: -723775.97 | G11: APLICA A FC 2-1310 | H11: - | I11: -
B12: 45407 | C12: FAC | D12: 200001315 | E12: =+B12+30 -> 45437 | F12: 1951725.6 | G12: DISEÑO MODIF DE BARCAZA | H12: SALDADA | I12: -
B13: 45407 | C13: FAC | D13: 200001316 | E13: =+B13+30 -> 45437 | F13: 723775.97 | G13: FEBRERO 2024 | H13: SALDADA | I13: -
B16: TOTAL DEVENGADO INFORMADO | F16: 0
B17: TOTAL FACTURADO | E17: total fact | F17: 0
B18: DIFERENCIA | E18: dif deveg | F18: =+F16-F17 -> 0
B20: TOTAL DEUDA | F20: 0

Sheet INDUMAT
B1: INDUMAT SA
B3: FECHA | C3: TIPO COMP | D3: NUMERO | E3: FECHA VTO | F3: IMPORTE | G3: OBSERVACIONES | H3: FECHA COBRO | I3: DS. DIF
B4: 45239 | C4: FAC | D4: 200001290 | E4: =+B4+10 -> 45249 | F4: 14027413 | H4: SALDADA | I4: -
B5: 45287 | C5: FAC | D5: 200001295 | E5: =+B5+10 -> 45297 | F5: 2951611.1 | G5: OCTUBRE MV44 | H5: SALDADA | I5: -
B6: 45287 | C6: FAC | D6: 200001296 | E6: =+B6+10 -> 45297 | F6: 8250015.8 | G6: OCTUBRE | H6: SALDADA | I6: -
B7: 45296 | C7: FAC | D7: 200001300 | E7: =+B7+10 -> 45306 | F7: 12437751 | G7: NOVIEMBRE | H7: 45369 | I7: =+B7-H7 -> -73
B8: 45296 | C8: FAC | D8: 200001301 | E8: =+B8+10 -> 45306 | F8: 4787116.1 | G8: NOVIEMBRE MV44 | H8: SALDADA | I8: -
B9: 45356 | C9: FAC | D9: 200001303 | E9: =+B9+30 -> 45386 | F9: 19949799 | G9: ENERO 2024 MV44 | H9: SALDADA | I9: -
B10: 45356 | C10: FAC | D10: 200001304 | E10: =+B10+30 -> 45386 | F10: 1802758.4 | G10: ENERO 2024 | H10: - | I10: -
B11: 45376 | C11: FAC | D11: 200001307 | E11: =+B11+30 -> 45406 | F11: 4772819.5 | G11: FEBRERO 2024 MV44 | H11: - | I11: -
B12: 45376 | C12: FAC | D12: 200001308 | E12: =+B12+30 -> 45406 | F12: 9144737.9 | G12: FEBRERO 2024 | H12: - | I12: -
B13: 45377 | C13: NC | D13: 200000091 | E13: =+B13+30 -> 45407 | F13: -4772819.5 | G13: APLICA A FC 2-1307 | H13: - | I13: -
B14: 45377 | C14: NC | D14: 200000092 | E14: =+B14+30 -> 45407 | F14: -9144737.9 | G14: APLICA A FC 2-1308 | H14: - | I14: -
B15: 45378 | C15: NC | D15: 200000097 | E15: =+B15+30 -> 45408 | F15: -6449960 | G15: APLICA A FC 2-1303/1304 | H15: - | I15: -
B16: 45407 | C16: FAC | D16: 200001313 | E16: =+B16+30 -> 45437 | F16: 4772819.5 | G16: FEBRERO 2024 MV44 | H16: SALDADA | I16: -
B17: 45407 | C17: FAC | D17: 200001314 | E17: =+B17+30 -> 45437 | F17: 9144737.9 | G17: FEBRERO 2024 | H17: SALDADA | I17: -
B18: 45440 | C18: FAC | D18: 200001323 | E18: =+B18+30 -> 45470 | F18: 12098634 | G18: MARZO 2024. | H18: SALDADA | I18: -
B19: 45446 | C19: FAC | D19: 200001326 | E19: =+B19+30 -> 45476 | F19: 8772500 | G19: ABRIL 2024. | H19: SALDADA | I19: -
B20: 45474 | C20: FAC | D20: 200001330 | E20: =+B20+30 -> 45504 | F20: 6500000 | G20: MTTO FLOTA | H20: SALDADA | I20: -
... B23: 45568 | C23: FAC | D23: 200001347 | E23: =+B23+30 -> 45598 | F23: 12556839 | G23: MTTO FLOTA | H23: SALDADA | I23: -
B24: 45600 | C24: FAC | D24: 200001351 | E24: =+B24+0 -> 45600 | F24: 12992462 | G24: MTTO FLOTA | H24: SALDADA | I24: -
B25: 45629 | C25: FAC | D25: A200001355 | E25: =+B25+0 -> 45629 | F25: 13342185 | G25: MTTO FLOTA | H25: SALDADA | I25: -
B26: 45659 | C26: FAC | D26: A200001359 | E26: =+B26+0 -> 45659 | F26: 13665941 | G26: MTTO FLOTA | H26: SALDADA | I26: -
B27: 45691 | C27: FAC | D27: A200001363 | E27: =+B27+30 -> 45721 | F27: 14035482 | G27: MTTO FLOTA | H27: SALDADA | I27: -
B28: 45721 | C28: FAC | D28: A200001368 | E28: =+B28+30 -> 45751 | F28: 14345813 | G28: MTTO FLOTA | H28: SALDADA | I28: -
B29: 45748 | C29: FAC | D29: A200001372 | E29: =+B29+30 -> 45778 | F29: 14690346 | G29: MTTO FLOTA | H29: SALDADA | I29: -
B30: 45769 | C30: FAC | D30: A200001377 | E30: =+B30+30 -> 45799 | F30: 480078.39 | G30: BURLETE APOYA PLUMA A TANQUE
B31: 45782 | C31: FAC | D31: A200001379 | E31: 45782 | F31: 15238198 | G31: MTTO FLOTA | H31: SALDADA | I31: -
B32: 45810 | C32: FAC | D32: A200001384 | E32: =+B32+30 -> 45840 | F32: 15661948 | G32: MTTO FLOTA | H32: SALDADA
B33: 45839 | C33: FAC | D33: A200001392 | E33: =+B33+30 -> 45869 | F33: 15897051 | G33: MTTO FLOTA | H33: SALDADA
B34: 45870 | C34: FAC | D34: A200001405 | E34: =+B34+30 -> 45900 | F34: 6160000 | G34: MTTO FLOTA | H34: SALDADA
B35: 45901 | C35: FAC | D35: A200001412 | E35: =+B35+30 -> 45931 | F35: 7746260.3 | G35: MTTO FLOTA | H35: SALDADA
B36: 45931 | C36: FAC | D36: A200001414 | E36: =+B36+30 -> 45961 | F36: 15171233 | G36: MTTO FLOTA | H36: SALDADA
B37: 45964 | C37: FAC | D37: A200001427 | E37: =+B37+30 -> 45994 | F37: 4265315.2 | G37: MTTO FLOTA | H37: SALDADA
B38: 45992 | C38: FAC | D38: A200001431 | E38: =+B38+30 -> 46022 | F38: 11987915 | G38: MTTO FLOTA | H38: SALDADA
B39: 46013 | C39: FAC | D39: A200001438 | E39: =+B39+30 -> 46043 | F39: 6863358.6 | G39: VENTA REPUESTOS IMPORTACION
B40: 46024 | C40: FAC | D40: A200001440 | E40: =+B40+30 -> 46054 | F40: 14359088 | G40: MTTO FLOTA
B43: TOTAL DEVENGADO INFORMADO | F43: 0
B44: TOTAL FACTURADO | E44: total fact
B45: DIFERENCIA | E45: dif deveg | F45: =+F43-F44 -> 0
...

Sheet ABSA
B1: ABSA
B3: FECHA | C3: TIPO COMP | D3: NUMERO | E3: FECHA VTO | F3: IMPORTE | G3: OBSERVACIONES | H3: FECHA COBRO | I3: DS. DIF
B4: 45350 | C4: FAC | D4: 300000024 | E4: =+B4+30 -> 45380 | F4: 4143320 | G4: REPARACIONES AA717YH NP 4500020628 | H4: - | I4: -
B5: 45363 | C5: NC | D5: 300000004 | E5: =+B5+30 -> 45393 | F5: -4143320 | G5: APLICA A FC 3-24 | H5: - | I5: -
B6: 45363 | C6: FAC | D6: 300000025 | E6: =+B6+30 -> 45393 | F6: 4143320 | G6: REPARACIONES AA717YH NP 4500020628 | H6: 45436 | I6: =+B6-H6 -> -73
B7: 45366 | C7: FAC | D7: 300000026 | E7: =+B7+30 -> 45396 | F7: 1006236 | G7: CODO GIRATORIO KIT DE CODO NP 4500020669 | H7: 45490 | I7: =+B7-H7 -> -124
B8: 45455 | C8: FAC | D8: 300000027 | E8: =+B8+30 -> 45485 | F8: 16694074 | G8: NP 4500021489 | H8: - | I8: -
B9: 45490 | C9: NC | D9: 300000005 | E9: =+B9+30 -> 45520 | F9: -16694074 | G9: APLICA A FC 3-27 | H9: - | I9: -
B10: 45492 | C10: FAC | D10: 300000028 | E10: =+B10+30 -> 45522 | F10: 16694074 | G10: NP 4500021489 | H10: 45520 | I10: =+B10-H10 -> -28
B11: 45504 | C11: FAC | D11: 300000029 | E11: =+B11+30 -> 45534 | F11: 2395800 | G11: TRABAJOS VARIOS NP 4500022374 AA717YH | H11: - | I11: -
B12: 45525 | C12: FAC | D12: 200001339 | E12: =+B12+30 -> 45555 | F12: 1064800 | G12: TRASLADOS AA717YM-AA717YL | H12: 45581 | I12: =+B12-H12 -> -56
B13: 45538 | C13: NC | D13: 300000006 | E13: =+B13+30 -> 45568 | F13: -2395800 | G13: APLICA A FC 3-6 | H13: - | I13: -
B14: 45560 | C14: FAC | D14: 300000030 | E14: =+B14+30 -> 45590 | F14: 25088835 | G14: TRABAJOS REPUESTOS | H14: 45597 | I14: =+B14-H14 -> -37
B15: 45573 | C15: FAC | D15: 300000031 | E15: =+B15+30 -> 45603 | F15: 2395800 | G15: TRABAJOS AA717YH | H15: 45597 | I15: =+B15-H15 -> -24
B16: 45574 | C16: FAC | D16: 300000032 | E16: =+B16+30 -> 45604 | F16: 34449608 | G16: SOPLADOR AA698SW | H16: 45590 | I16: =+B16-H16 -> -16
B17: 45636 | C17: FAC | D17: A300000034 | E17: =+B17+30 -> 45666 | F17: 6551015 | G17: CILINDRO DE TANQUE AA698SW OC 4500024525 | H17: 45653 | I17: =+B17-H17 -> -17
B18: 45664 | C18: FAC | D18: A300000035 | E18: =+B18+30 -> 45694 | F18: 15923950 | G18: REPARACIONES AA698SW NP 4500021713 | H18: 45702 | I18: =+B18-H18 -> -38
B19: 45692 | C19: FAC | D19: A300000036 | E19: =+B19+30 -> 45722 | F19: 3687332.3 | G19: REPARACIONES AA717YI NP 4500025456 | H19: 45722 | I19: =+B19-H19 -> -30
B20: 45695 | C20: FAC | D20: A300000037 | E20: =+B20+30 -> 45725 | F20: 41127428 | G20: REPARACIONES AA717YL/AA717YM PEDIDO 4500025133 | H20: 45722 | I20: =+B20-H20 -> -27
B21: 45736 | C21: FAC | D21: A300000038 | E21: =+B21+30 -> 45766 | F21: 15584771 | G21: REPARACIONES AA717YI NP 4500026290 | H21: - | I21: -
B22: 45756 | C22: NC | D22: A300000007 | E22: =+B22+30 -> 45786 | F22: 15584771 | G22: APLICA A FC 3-38 | H22: - | I22: -
B23: 45756 | C23: FAC | D23: A300000039 | E23: =+B23+30 -> 45786 | F23: 7792385.5 | G23: REPARACIONES AA717YI NP 4500026290 ANTICIPO 50% | H23: 45772 | I23: =+B23-H23 -> -16
B24: 45796 | C24: FAC | D24: A300000040 | E24: =+B24+30 -> 45826 | F24: =17050998.14 -> 17050998 | G24: REPARACIONES DOMINIO HEZ261 | H24: 45821 | I24: =+B24-H24 -> -25
B25: 45812 | C25: FAC | D25: A300000041 | E25: =+B25+30 -> 45842 | F25: 15584771 | G25: REPARACIONES AA717YI NP 4500026290 | H25: 45841 | I25: =+B25-H25 -> -29
B26: 45813 | C26: NC | D26: A300000008 | E26: =+B26+30 -> 45843 | F26: -7792385.5 | G26: APLICA A FC 3-41 | H26: 45841 | I26: =+B26-H26 -> -28
B27: 45834 | C27: FAC | D27: A300000042 | E27: =+B27+30 -> 45864 | F27: 13036297 | G27: REPARACIONES AA698SW NP 4500027506 RTO4567 | H27: 45854 | I27: =+B27-H27 -> -20
B28: 45835 | C28: FAC | D28: A300000043 | E28: =+B28+30 -> 45865 | F28: 42411468 | G28: BLOWER SOPLADOR DE AIRE EQUIPO JET VAC 4075 44717YM NP4500027607 RTO4568 | H28: - | I28: -
B29: 45854 | C29: NC | D29: A300000009 | E29: 45885 | F29: -42411468 | G29: BLOWER SOPLADOR DE AIRE EQUIPO JET VAC 4075 44717YM NP4500027607 RTO4568 | H29: - | I29: -
B30: 45839 | C30: FAC | D30: A200001394 | E30: =+B30+30 -> 45869 | F30: 9634719.3 | G30: REP. DE CJ DE TRANSFERENCIA DOMINIO: AA-717-YL NPº: 4500027912 Nº DE REMITO: 4569 | H30: - | I30: -
B31: 45842 | C31: FAC | D31: A200001395 | E31: =+B31+30 -> 45872 | F31: 9778860.3 | G31: REP. CILINDRO DOMINIO: AA-717-YL NPº: 4500027761 Nº DE REMITO: 4570 | H31: 45855 | I31: =+B31-H31 -> -13
B32: 45855 | C32: FAC | D32: A200001396 | E32: =+B32+30 -> 45885 | F32: 42411468 | G32: BLOWER SOPLADOR DE AIRE EQUIPO JET VAC 4075 44717YM NP4500027607 RTO4568 | H32: 45918 | I32: =+B32-H32 -> -63
B33: 45869 | C33: NC | D33: A200000101 | E33: =+B33+30 -> 45899 | F33: -9634719.3 | G33: REP. DE CJ DE TRANSF. DOMINIO: AA-717-YL NPº: 4500027912 Nº DE REMITO: 4569 APLICA FC 1394 | H33: - | I33: -
B34: 45869 | C34: FAC | D34: A200001399 | E34: =+B34+30 -> 45899 | F34: 9634719.3 | G34: REP. DE CJ DE TRANSF. DOMINIO: AA-717-YL NPº: 450008490 Nº DE REMITO: 4569 | H34: 45918 | I34: =+B34-H34 -> -49
B35: 45869 | C35: FAC | D35: A200001400 | E35: =+B35+30 -> 45899 | F35: 988267.5 | G35: CABLE ACELERADOR BOMBA DE AGUA LLAVE DE ACCIONAMIENTO DOMINIO AA717YI NPº4500028299 REMITO 4574 | H35: 45918 | I35: =+B35-H35 -> -49
B36: 45926 | C36: FAC | D36: A200001413 | E36: =+B36+30 -> 45956 | F36: 771220.12 | G36: DIAGNOSTICO, DESARME E INFORME DOMINIO AA717YL OC 4500029404 | H36: - | I36: -
B37: 45946 | C37: NC | D37: A200000102 | E37: =+B37+30 -> 45976 | F37: -771220.12 | G37: DIAGNOSTICO, DESARME E INFORME DOMINIO AA717YL OC 4500029404 APLICA A FC 1413 | H37: - | I37: -
B38: 45946 | C38: FAC | D38: A200001420 | E38: 45976 | F38: 807520.12 | G38: DIAGNOSTICO, DESARME E INFORME DOMINIO AA717YL OC 4500029404 | H38: 45986 | I38: =+B38-H38 -> -40
B39: 45971 | C39: FAC | D39: A200001430 | E39: =+B39+30 -> 46001 | F39: 20104860 | G39: REPARACIONES DOMINIO: HEZ261 NPº: 4500029647 | H39: 46013 | I39: =+B39-H39 -> -42
B42: TOTAL DEVENGADO INFORMADO | F42: 0
B43: TOTAL FACTURADO | E43: total fact | F43: 0
...

Sheet ADESSO
B1: ADESSO
B3: FECHA | C3: TIPO COMP | D3: NUMERO | E3: FECHA VTO | F3: IMPORTE | G3: OBSERVACIONES | H3: FECHA COBRO | I3: DS. DIF
B4: 45673 | C4: FAC | D4: A200001362 | E4: =+B4+0 -> 45673 | F4: 1500333.4 | G4: tobera aluminio | H4: 45673 | I4: =+B4-H4 -> 0
B7: TOTAL DEVENGADO INFORMADO | F7: 0
B8: TOTAL FACTURADO | E8: total fact | F8: 0
B9: DIFERENCIA | E9: dif deveg | F9: =+F7-F8 -> 0
B11: TOTAL DEUDA | F11: 0

Sheet AGUAS RIONEGRINAS
B1: AGUAS RIONEGRINAS
B3: FECHA | C3: TIPO COMP | D3: NUMERO | E3: FECHA VTO | F3: IMPORTE | G3: OBSERVACIONES | H3: FECHA COBRO | I3: DS. DIF
B4: 45513 | C4: FAC | D4: 200001338 | E4: =+B4+30 -> 45543 | F4: 11417015 | G4: RODAMIENTO 33 Y 53 DIENTES - EJE DE CCAJA COTA | H4: 45524 | I4: =+B4-H4 -> -11
B5: 45513 | C5: FAC | E5: =+B5+30 -> 45543 | F5: 11417015 | G5: RODAMIENTO 33 Y 53 DIENTES - EJE DE CCAJA COTA | H5: 45516 | I5: =+B5-H5 -> -3
B6: 45538 | C6: FAC | D6: 200001344 | E6: =+B6+0 -> 45538 | F6: 2779134 | G6: EMBRAGUE CAJA COTTA | H6: 45545 | I6: =+B6-H6 -> -7
B7: 45538 | C7: FAC | E7: 45538 | F7: =2726193.94+11484.03+41456.08 -> 2779134 | G7: EMBRAGUE CAJA COTTA | H7: 45540 | I7: =+B7-H7 -> -2
B8: 45856 | C8: FAC | D8: 200001397 | E8: =+B8+30 -> 45886 | F8: 42776989 | G8: EQUIPO AGUATECH DOM KRD066 OC699-2025 50% ANT 50%CONT | H8: 11-8 Y 23-10
B11: TOTAL DEVENGADO INFORMADO | F11: 0
B12: TOTAL FACTURADO | E12: total fact | F12: 0
B13: DIFERENCIA | E13: dif deveg | F13: =+F11-F12 -> 0
B15: TOTAL DEUDA | F15: 0

Sheet ALEMARSA
B1: ALEMARSA
B3: FECHA | C3: TIPO COMP | D3: NUMERO | E3: FECHA VTO | F3: IMPORTE | G3: OBSERVACIONES | H3: FECHA COBRO | I3: DS. DIF
B4: 46030 | C4: FAC | D4: A200001444 | E4: =+B4+30 -> 46060 | F4: 2292780.6 | G4: TOBERA ALUMINIO 1" PARA EQUIPO DESOBSTRUCTOR | H4: 46031 | I4: =+B4-H4 -> -1
B7: TOTAL DEVENGADO INFORMADO | F7: 0
B8: TOTAL FACTURADO | E8: total fact | F8: 0
B9: DIFERENCIA | E9: dif deveg | F9: =+F7-F8 -> 0
B11: TOTAL DEUDA | F11: 0

Sheet COOP. COSERCO CORONDA
B1: COOP. COSERCO CORONDA
B3: FECHA | C3: TIPO COMP | D3: NUMERO | E3: FECHA VTO | F3: IMPORTE | G3: OBSERVACIONES | H3: FECHA COBRO | I3: DS. DIF
B4: 45992 | C4: FAC | D4: 200001437 | E4: =+B4+30 -> 46022 | F4: 4283400 | G4: MANG. DESOBTRUCTORA PREDATOR 3/4" REF BNA VTA 1475 | H4: 46006 | I4: =+B4-H4 -> -14
B7: TOTAL DEVENGADO INFORMADO | F7: 0
B8: TOTAL FACTURADO | E8: total fact | F8: 0
B9: DIFERENCIA | E9: dif deveg | F9: =+F7-F8 -> 0
B11: TOTAL DEUDA | F11: 0

Sheet COOP OB Y SERV ST TERESITA 
B1: COOP. DE OBRAS Y SERV SANTA TERESITA
B3: FECHA | C3: TIPO COMP | D3: NUMERO | E3: FECHA VTO | F3: IMPORTE | G3: OBSERVACIONES | H3: FECHA COBRO | I3: DS. DIF
B4: 45856 | C4: FAC | D4: 200001398 | E4: =+B4+30 -> 45886 | F4: 1748371.4 | G4: TOBERA OVOIDAL TOBERAS MEDUNA OC 20250004 | H4: 45859 | I4: =+B4-E4 -> -30
B7: TOTAL DEVENGADO INFORMADO | F7: 0
B8: TOTAL FACTURADO | E8: total fact | F8: 0
B9: DIFERENCIA | E9: dif deveg | F9: =+F7-F8 -> 0
B11: TOTAL DEUDA | F11: 0

Sheet DESOB.ARGENTINA ASHIRA
B1: DESOBSTRUCTORA ARG. ASHIRA
B3: FECHA | C3: TIPO COMP | D3: NUMERO | E3: FECHA VTO | F3: IMPORTE | G3: OBSERVACIONES | H3: FECHA COBRO | I3: DS. DIF
B4: 45897 | C4: FAC | D4: 200001406 | E4: =+B4+30 -> 45927 | F4: 2640027.6 | G4: TOBERA OVOIDAL TOBERAS SAPO 1" OC 98-2987 | H4: 45903 | I4: =+B4-H4 -> -6
B7: TOTAL DEVENGADO INFORMADO | F7: 0
B8: TOTAL FACTURADO | E8: total fact | F8: =+F4 -> 2640027.6
B9: DIFERENCIA | E9: dif deveg | F9: =+F7-F8 -> -2640027.6
B11: TOTAL DEUDA | F11: 0

Sheet ENTE MUNIC SERV
B1: ENTE MUNICIPAL DE SERVICIOS URBANOS O.P.
B3: FECHA | C3: TIPO COMP | D3: NUMERO | E3: FECHA VTO | F3: IMPORTE | G3: OBSERVACIONES | H3: FECHA COBRO | I3: DS. DIF
B4: 45775 | C4: FAC | D4: A200001378 | E4: =+B4+5 -> 45780 | F4: 4235000 | G4: TRASLADO LA PAMPA - BS AS OC 487 | H4: 45835 | I4: =+B4-H4 -> -60
B5: 45798 | C5: FAC | D5: A200001383 | E5: 45798 | F5: 35368393 | G5: ADAPTACION CAJA DE TRANSFERENCIA | H5: 45939 | I5: =+B5-H5 -> -141
B6: 45957 | C6: FAC | D6: A200001421 | E6: 45957 | F6: 394763.71 | G6: BATERIA MOURA 12X180 OC Nº1139 | H6: 46020 | I6: =+B6-H6 -> -63
B9: TOTAL DEVENGADO INFORMADO | F9: 0
B10: TOTAL FACTURADO | E10: total fact | F10: =+F4+F5+F6 -> 39998157
B11: DIFERENCIA | E11: dif deveg | F11: =+F9-F10 -> -39998157
B13: TOTAL DEUDA | F13: 0

Sheet MUNIC BERAZATEGUI
B1: MUNIC BERAZATEGUI
B3: FECHA | C3: TIPO COMP | D3: NUMERO | E3: FECHA VTO | F3: IMPORTE | G3: OBSERVACIONES | H3: FECHA COBRO | I3: DS. DIF
B4: 45492 | C4: FAC | D4: 200000312 | E4: =+B4+0 -> 45492 | F4: 570429.09 | G4: RELAY POTTER & BRUMFIELD 12V | H4: 45498 | I4: =+B4-H4 -> -6
B5: 45573 | C5: FAC | D5: 200000318 | E5: =+B5+30 -> 45603 | F5: 1176985 | G5: REPARACIONES FTS470 OC 2209 | H5: 45579 | I5: =+B5-H5 -> -6
B6: 45621 | C6: FAC | D6: B200000319 | E6: =+B6+0 -> 45621 | F6: 3870363 | G6: REPUESTOS FTS470 OC 2520 | H6: - | I6: -
B7: 45623 | C7: NC | D7: B200000053 | E7: =+B7+0 -> 45623 | F7: -3870363 | H7: - | I7: -
B8: 45623 | C8: FAC | D8: B200000320 | E8: =+B8+0 -> 45623 | F8: 3870363 | G8: REPUESTOS FTS470 OC 2520 | H8: 45630 | I8: =+B8-H8 -> -7
B11: TOTAL DEVENGADO INFORMADO | F11: 0
B12: TOTAL FACTURADO | E12: total fact | F12: 0
B13: DIFERENCIA | E13: dif deveg | F13: =+F11-F12 -> 0
B15: TOTAL DEUDA | F15: 0

Sheet MUNIC JUNIN
B1: MUNIC JUNIN
B3: FECHA | C3: TIPO COMP | D3: NUMERO | E3: FECHA VTO | F3: IMPORTE | G3: OBSERVACIONES | H3: FECHA COBRO | I3: DS. DIF
B4: 45503 | C4: FAC | D4: 200000313 | E4: =+B4+30 -> 45533 | F4: 9382364.2 | G4: MANGUERA DESOBSTRUCTORA | H4: 45511 | I4: =+B4-H4 -> -8
B5: 45518 | C5: FAC | D5: 200000314 | E5: =+B5+30 -> 45548 | F5: 1642817 | G5: VALVULA - FILTRO DE MALLA | H5: 45534 | I5: =+B5-H5 -> -16
B6: 45531 | C6: FAC | D6: 200000316 | E6: =+B6+30 -> 45561 | F6: 1417659 | G6: TOBERA GRANADA3/4 - OVOIDAL 3/4 | H6: 45548 | I6: =+B6-H6 -> -17
B7: 45559 | C7: FAC | D7: 200000317 | E7: =+B7+30 -> 45589 | F7: 20000000 | G7: REPARACION LWV091 | H7: 45602 | I7: =+B7-H7 -> -43
B8: 45559 | C8: FAC | E8: =+B8+30 -> 45589 | F8: 20541774 | G8: REPARACION LWV091 | H8: 45579 | I8: =+B8-H8 -> -20
B9: 45722 | C9: FAC | D9: B200000323 | E9: =+B9+30 -> 45752 | F9: 7018911 | G9: REPARACION MANGUERA DESOBSTRUCTORA | H9: - | I9: -
B10: 45723 | C10: NC | D10: B200000055 | E10: =+B10+30 -> 45753 | F10: -7018911 | G10: REPARACION MANGUERA DESOBSTRUCTORA | H10: - | I10: -
B11: 45723 | C11: FAC | D11: B200000324 | E11: =+B11+30 -> 45753 | F11: 8492882.3 | G11: REPARACION MANGUERA DESOBSTRUCTORA | H11: 45785 | I11: =+B11-H11 -> -62
B12: 45813 | C12: FAC | D12: B200000326 | E12: 45813 | F12: 20551910 | G12: REPARACION GRAL EQUIPO JET VAC 4500 D OC: 5058 ANT FINANC | H12: 45817 | I12: =+B12-H12 -> -4
B13: 45849 | C13: FAC | D13: B200000328 | E13: =+B13+30 -> 45879 | F13: 3953308 | G13: KIT DE REPARACION BOMBA DE AGUA KF36 OC6256 DOMINIO AB949NT | H13: - | I13: -
B14: 45849 | C14: NC | D14: B200000057 | E14: =+B14+30 -> 45879 | F14: -3953308 | G14: KIT DE REPARACION BOMBA DE AGUA KF36 OC6256 DOMINIO AB949NT | H14: - | I14: -
B15: 45852 | C15: FAC | D15: B200000329 | E15: =+B15+30 -> 45882 | F15: 4783502.7 | G15: KIT DE REPARACION BOMBA DE AGUA KF36 OC6256 DOMINIO AB949NT | H15: 45897 | I15: =+B15-H15 -> -45
B16: 45859 | C16: FAC | D16: B200000330 | E16: =+B16+30 -> 45889 | F16: 3795836.5 | G16: TOBERAS Nº OC 6944DOMINIO LWV-091 | H16: 45880 | I16: =+B16-H16 -> -21
B17: 45881 | C17: FAC | D17: B200000333 | E17: =+B17+30 -> 45911 | F17: 305780.31 | G17: 4 TERMINAL HG 2-1/2" PARA MANGUERA OC 7769 DOMINIO LWV 091 | H17: - | I17: -
B18: 45881 | C18: NC | D18: B200000059 | E18: =+B18+30 -> 45911 | F18: -305780.31 | G18: 4 TERMINAL HG 2-1/2" PARA MANGUERA OC 7769 DOMINIO LWV 091 PLIACA FC 333 | H18: - | I18: -
B19: 45881 | C19: FAC | D19: B200000334 | E19: 45911 | F19: 1223121.2 | G19: 4 TERMINAL HG 2-1/2" PARA MANGUERA OC 7769 DOMINIO LWV 091 | H19: 45888 | I19: =+B19-H19 -> -7
B20: 45901 | C20: FAC | D20: B200000335 | E20: =+B20+30 -> 45931 | F20: 20551910 | G20: REP. EQUIPO JET VAC 4500D OC5058 AB949NT | H20: 45925 | I20: =+B20-H20 -> -24
B21: 46045 | C21: FAC | D21: B200000339 | E21: =+B21+30 -> 46075 | F21: 7631712 | G21: 2 MANGUERAS DESOBSTRUCTORAS EN 3/4"
B24: TOTAL DEVENGADO INFORMADO | F24: 0
B25: TOTAL FACTURADO | E25: total fact | F25: =+F12+F13+F14+F15+F16+F17+F18+F19+F11+F9+F10+F20 -> 59399163
B26: DIFERENCIA | E26: dif deveg | F26: =+F24-F25 -> -59399163
B28: TOTAL DEUDA | F28: =+F21 -> 7631712

Sheet MUNIC SANTA ROSA
B1: MUNIC SANTA ROSA
B3: FECHA | C3: TIPO COMP | D3: NUMERO | E3: FECHA VTO | F3: IMPORTE | G3: OBSERVACIONES | H3: FECHA COBRO | I3: DS. DIF
B4: 45945 | C4: FAC | D4: B0000200000336 | F4: 394763.71 | G4: BATERIA MOURA 12X180 OC Nº1139 | H4: - | I4: -
B5: 45957 | C5: NC | D5: B0000200000060 | F5: -394763.71 | G5: BATERIA MOURA 12X180 OC Nº1139 APLICA A FC336 | H5: - | I5: -
F6: ,
B8: TOTAL DEVENGADO INFORMADO | F8: 0
B9: TOTAL FACTURADO | E9: total fact | F9: 0
B10: DIFERENCIA | E10: dif deveg | F10: =+F8-F9 -> 0
B12: TOTAL DEUDA | F12: 0

Sheet MUNIC SAN MARTIN
B1: MUNIC SAN MARTIN
B3: FECHA | C3: TIPO COMP | D3: NUMERO | E3: FECHA VTO | F3: IMPORTE | G3: OBSERVACIONES | H3: FECHA COBRO | I3: DS. DIF
B4: 44266 | C4: FAC | D4: B0000200000266 | F4: 260275
B5: 44685 | C5: FAC | D5: B0000200000287 | F5: 942053
B8: TOTAL DEVENGADO INFORMADO | F8: 0
B9: TOTAL FACTURADO | E9: total fact | F9: 0
B10: DIFERENCIA | E10: dif deveg | F10: =+F8-F9 -> 0
B12: TOTAL DEUDA | F12: =+F5+F4 -> 1202328

Sheet MUNIC TRES ARROYOS
B1: MUNIC TRES ARROYOS
B3: FECHA | C3: TIPO COMP | D3: NUMERO | E3: FECHA VTO | F3: IMPORTE | G3: OBSERVACIONES | H3: FECHA COBRO | I3: DS. DIF
B4: 45344 | C4: FAC | D4: 200000310 | E4: =+B4+5 -> 45349 | F4: 3003028.4 | G4: MANGUERA | H4: 45371 | I4: =+B4-H4 -> -27
B5: 45344 | C5: FAC | E5: 45349 | F5: 3003028.4 | G5: MANGUERA | H5: 45351 | I5: =+B5-H5 -> -7
B6: 45714 | C6: FAC | D6: B200000321 | E6: =+B6+0 -> 45714 | F6: 19980631 | G6: REPARACIONES DAT754 | H6: - | I6: -
B7: 45715 | C7: NC | D7: B200000054 | E7: =+B7+0 -> 45715 | F7: -19980631 | G7: APLICA A FC 2-321 | H7: - | I7: -
B8: 45715 | C8: FAC | D8: B200000322 | E8: =+B8+0 -> 45715 | F8: 19980631 | G8: REPARACIONES DAT754 | H8: - | I8: -
B9: 45729 | C9: NC | D9: B200000056 | E9: =+B9+0 -> 45729 | F9: -19980631 | G9: APLICA A FC 2-322 | H9: - | I9: -
B10: 45729 | C10: FAC | D10: B200000325 | E10: =+B10+0 -> 45729 | F10: 19980631 | G10: REPARACIONES DAT754 | H10: 45733 | I10: =+B10-H10 -> -4
B11: 45846 | C11: FAC | D11: B200000327 | E11: =+B11+0 -> 45846 | F11: 7160000 | G11: MANGUERA DESOB. DIAMETRO 1"X152M OC2938 | H11: 45868 | I11: =+B11-H11 -> -22
B12: 45861 | C12: FAC | D12: B200000331 | E12: =+B12+0 -> 45861 | F12: 13472938 | G12: REPARACIONES OC 3035 DOMINIO DAT 754 VACTOR
B13: 45863 | C13: NC | D13: B200000058 | E13: =+B13+0 -> 45863 | F13: -13472938 | G13: REPARACIONES OC 3035 DOMINIO DAT 754 VACTOR
B14: 45866 | C14: FAC | D14: B200000332 | E14: =+B14+0 -> 45866 | F14: 13472938 | G14: REPARACIONES OC 3035 DOMINIO DAT 754 VACTOR | H14: 45888 | I14: =+B14-H14 -> -22
B17: TOTAL DEVENGADO INFORMADO | F17: 0
B18: TOTAL FACTURADO | E18: total fact | F18: =+F11+F14 -> 20632938
B19: DIFERENCIA | E19: dif deveg | F19: =+F17-F18 -> -20632938
B21: TOTAL DEUDA | F21: 0

Sheet OB SANIT MDP
B1: OBRAS SANITARIAS MAR DEL PLATA
B3: FECHA | C3: TIPO COMP | D3: NUMERO | E3: FECHA VTO | F3: IMPORTE | G3: OBSERVACIONES | H3: FECHA COBRO | I3: DS. DIF
B4: 45520 | C4: FAC | D4: 200000315 | E4: =+B4+30 -> 45550 | F4: 805134 | G4: BURLETE P/ JUNTA TANQUE JET-VAC 4075. | H4: 45565 | I4: =+B4-H4 -> -45
B5: 46035 | C5: FAC | D5: 200000337 | E5: =+B5+30 -> 46065 | F5: 6865454.5 | G5: ABRAZADERAS RAPIDAS 8" PARA JET VAC | H5: - | I5: -
B6: 46036 | C6: NC | D6: 200000061 | E6: =+B6+30 -> 46066 | F6: -6865454.5 | G6: APLICA A FC 2-337 | H6: - | I6: -
B7: 46036 | C7: FAC | D7: 200000338 | E7: =+B7+30 -> 46066 | F7: 8307200 | G7: ABRAZADERAS RAPIDAS 8" PARA JET VAC
B10: TOTAL DEVENGADO INFORMADO | F10: 0
B11: TOTAL FACTURADO | E11: total fact | F11: 0
B12: DIFERENCIA | E12: dif deveg | F12: =+F10-F11 -> 0
B14: TOTAL DEUDA | F14: =+F7 -> 8307200

Sheet SERV AGUA MISIONES
B1: SERVICIOS DE AGUA DE MISIONES
B3: FECHA | C3: TIPO COMP | D3: NUMERO | E3: FECHA VTO | F3: IMPORTE | G3: OBSERVACIONES | H3: FECHA COBRO | I3: DS. DIF
B4: 45756 | C4: FAC | D4: A200001376 | E4: =+B4+30 -> 45786 | F4: 2710167.7 | G4: TOBERAS | H4: 45772 | I4: =+B4-H4 -> -16
B7: TOTAL DEVENGADO INFORMADO | F7: 0
B8: TOTAL FACTURADO | E8: total fact | F8: 0
B9: DIFERENCIA | E9: dif deveg | F9: =+F7-F8 -> 0
B11: TOTAL DEUDA | F11: 0

Sheet SERV IBARRA
B1: SERVICIOS IBARRA
B3: FECHA | C3: TIPO COMP | D3: NUMERO | E3: FECHA VTO | F3: IMPORTE | G3: OBSERVACIONES | H3: FECHA COBRO | I3: DS. DIF
B4: 45442 | C4: FAC | D4: 200001325 | E4: =+B4+0 -> 45442 | F4: 968000 | G4: BOYA ACERO INOX PARA FLOTANTE 10" | H4: 45442 | I4: =+B4-H4 -> 0
B5: 45692 | C5: FAC | D5: A200001367 | E5: =+B5+30 -> 45722 | F5: 4713890.3 | G5: COLOC TANQUE DE AGUA 1150LT COLOC SUNCHO | H5: 45768 | I5: =+B5-H5 -> -76
B6: 45692 | C6: FAC | E6: 45722 | F6: 4875843.7 | G6: COLOC TANQUE DE AGUA 1150LT COLOC SUNCHO | H6: 45700 | I6: =+B5-H6 -> -8
B7: 45967 | C7: FAC | D7: A200001429 | E7: =+B7+5 -> 45972 | F7: 724608.5 | G7: BURLETE DE PLUMA ARMADO | H7: 45967 | I7: =+B7-H7 -> 0
B10: TOTAL DEVENGADO INFORMADO | F10: 0
B11: TOTAL FACTURADO | E11: total fact | F11: =+F4+F5+F6+F7 -> 11282342
B12: DIFERENCIA | E12: dif deveg | F12: =+F10-F11 -> -11282342
B14: TOTAL DEUDA | F14: 0

Sheet SOC COOP
B1: SOCIEDAD COOPERATIVA POPULAR LIMITADA
B3: FECHA | C3: TIPO COMP | D3: NUMERO | E3: FECHA VTO | F3: IMPORTE | G3: OBSERVACIONES | H3: FECHA COBRO | I3: DS. DIF
B4: 45609 | C4: FAC | D4: A300000033 | E4: =+B4+0 -> 45609 | F4: 9869493.3 | G4: REPUESTOS CAMBIO DÓLAR BNA $1.014,50 | H4: 45618 | I4: =+B4-H4 -> -9
B7: TOTAL DEVENGADO INFORMADO | F7: 0
B8: TOTAL FACTURADO | E8: total fact | F8: 0
B9: DIFERENCIA | E9: dif deveg | F9: =+F7-F8 -> 0
B11: TOTAL DEUDA | F11: 0

Sheet RESUMEN 2026
B1: OCME S.A.
B2: =TODAY() -> 46045
B3: SALDOS CLIENTES
B4: RAZON SOCIAL | C4: SALDO
B6: CAMPO FUERTE | C6: =+'CAMPO FUERTE'!F12 -> 0
B7: AUTOMAT | C7: =+AUTOMAT!F104 -> 21436431
B8: FLUVIOMAT | C8: =+FLUVIOMAT!F20 -> 0
B9: INDUMAT | C9: =+INDUMAT!F47 -> 7343436.9
B10: ABSA | C10: =+ABSA!F46 -> 0
B11: ADESSO | C11: =+ADESSO!F11 -> 0
B12: =+'AGUAS RIONEGRINAS'!B1 -> AGUAS RIONEGRINAS | C12: =+'AGUAS RIONEGRINAS'!F15 -> 0
B13: ALEMARSA | C13: =+ALEMARSA!F11 -> 0
B14: =+'COOP. COSERCO CORONDA'!B1 -> COOP. COSERCO CORONDA | C14: =+'COOP. COSERCO CORONDA'!F11 -> 0
B15: =+'COOP OB Y SERV ST TERESITA '!B1 -> COOP. DE OBRAS Y SERV SANTA TERESITA | C15: =+'COOP OB Y SERV ST TERESITA '!F11 -> 0
B16: =+'DESOB.ARGENTINA ASHIRA'!B1 -> DESOBSTRUCTORA ARG. ASHIRA | C16: =+'DESOB.ARGENTINA ASHIRA'!F11 -> 0
B17: ENTE MUNIC SERV URBANOS | C17: =+'ENTE MUNIC SERV'!F13 -> 0
B18: MUNIC JUNIN | C18: =+'MUNIC JUNIN'!F28 -> 7631712
B19: MUNIC SAN MARTIN | C19: =+'MUNIC SAN MARTIN'!F12 -> 1202328
B20: =+'MUNIC SANTA ROSA'!B1 -> MUNIC SANTA ROSA | C20: =+'MUNIC SANTA ROSA'!F12 -> 0
B21: MUNIC TRES ARROYOS | C21: =+'MUNIC TRES ARROYOS'!F21 -> 0
B22: OBRAS SANIT MDP | C22: =+'OB SANIT MDP'!F14 -> 8307200
B23: SERVICIOS DE AGUA DE MISIONES | C23: =+'SERV AGUA MISIONES'!F11 -> 0
B24: SERVICIOS IBARRA | C24: =+'SERV IBARRA'!F14 -> 0
B25: TOTAL A COBRAR A LA FECHA | C25: =SUM(C6:C24) -> 45921108
B26: SALDO TANGO | C26: =+'saldo tango'!C393 -> 45920338
C27: =+C25-C26 -> 770.02

Sheet saldo tango
A1: COD_CLIENT | B1: RAZON_SOCI | C1: SALDO
A2: 100028 | B2: AUTOMAT ARGENTINA S.A. | C2: 18149805
A3: 100035 | B3: AGUAS BONAERENSES S.A. | C3: 63240150
A4: 100077 | B4: AGUAS DE ZARATE S.A. P.E.M. | C4: -575.58
A5: 100107 | B5: SOLUC.QUIMICAS S.A.- MANTELECTRIC ICISA .UTE | C5: 0.01
A6: 100133 | B6: CAMPO FUERTE S.A. | C6: 15730000
A7: 100184 | B7: INDUMAT GROUP S.A. | C7: 480078.39
A8: 100190 | B8: ENTE MUNICIPAL DE SERVICIOS URBANOS O. P. | C8: 39603393
A9: 200011 | B9: MUNICIPALIDAD GRAL.SAN MARTIN | C9: 1202328
A10: 200011 | B10: MUNICIPALIDAD GRAL.SAN MARTIN | C10: 1202328
A11: 200023 | B11: MUNICIPALIDAD DE JUNIN | C11: 20551910
C12: =SUM(C3:C11) -> 1.4200961e+08
B14: 45821
A15: COD_CLIENT | B15: RAZON_SOCI | C15: SALDO
A16: 100028 | B16: AUTOMAT ARGENTINA S.A. | C16: 34049055
A17: 100035 | B17: AGUAS BONAERENSES S.A. | C17: 24843384
A18: 100077 | B18: AGUAS DE ZARATE S.A. P.E.M. | C18: -575.58
A19: 100107 | B19: SOLUC.QUIMICAS S.A.- MANTELECTRIC ICISA .UTE | C19: 0.01
A20: 100133 | B20: CAMPO FUERTE S.A. | C20: 15730000
A21: 100184 | B21: INDUMAT GROUP S.A. | C21: 8311052.2
A22: 100190 | B22: ENTE MUNICIPAL DE SERVICIOS URBANOS O. P. | C22: 39603393
A23: 200011 | B23: MUNICIPALIDAD GRAL.SAN MARTIN | C23: 1202328
C24: =SUM(C16:C23) -> 1.2373864e+08
B26: 45828
A27: COD_CLIENT | B27: RAZON_SOCI | C27: SALDO
A28: 100028 | B28: AUTOMAT ARGENTINA S.A. | C28: =18149805.07+194.45 -> 18150000
A29: 100035 | B29: AGUAS BONAERENSES S.A. | C29: 7792385.5
A30: 100077 | B30: AGUAS DE ZARATE S.A. P.E.M. | C30: -575.58
A31: 100107 | B31: SOLUC.QUIMICAS S.A.- MANTELECTRIC ICISA .UTE | C31: 0.01
A32: 100133 | B32: CAMPO FUERTE S.A. | C32: 15730000
A33: 100184 | B33: INDUMAT GROUP S.A. | C33: 480078.39
A34: 100190 | B34: ENTE MUNICIPAL DE SERVICIOS URBANOS O. P. | C34: 39603393
A35: 200011 | B35: MUNICIPALIDAD GRAL.SAN MARTIN | C35: 1202328
C36: =SUM(C28:C35) -> 82957609
B38: 45835
A39: COD_CLIENT | B39: RAZON_SOCI | C39: SALDO
A40: 100028 | B40: AUTOMAT ARGENTINA S.A. | C40: 18149805
A41: 100035 | B41: AGUAS BONAERENSES S.A. | C41: 63240150
A42: 100077 | B42: AGUAS DE ZARATE S.A. P.E.M. | C42: -575.58
A43: 100107 | B43: SOLUC.QUIMICAS S.A.- MANTELECTRIC ICISA .UTE | C43: 0.01
...
